Running experiments with C=800
/var/slurmd/spool/slurmd/job61853735/slurm_script: line 35: ./run_experiments.sh: No such file or directory
Error processing results: [Errno 2] No such file or directory: 'data/explorescore_sims100_C800_20241209_214747.csv'
Traceback (most recent call last):
  File "/net/rcstorenfs02/ifs/rc_labs/idreos_lab/users/vcainamisir/2048/2048rl/cpp/plotting/plot_results.py", line 122, in <module>
    main()
  File "/net/rcstorenfs02/ifs/rc_labs/idreos_lab/users/vcainamisir/2048/2048rl/cpp/plotting/plot_results.py", line 115, in main
    output_path = analyze_and_plot(args.csv_file)
  File "/net/rcstorenfs02/ifs/rc_labs/idreos_lab/users/vcainamisir/2048/2048rl/cpp/plotting/plot_results.py", line 79, in analyze_and_plot
    df = pd.read_csv(csv_path)
  File "/n/home06/vcainamisir/.local/lib/python3.10/site-packages/pandas/io/parsers/readers.py", line 1026, in read_csv
    return _read(filepath_or_buffer, kwds)
  File "/n/home06/vcainamisir/.local/lib/python3.10/site-packages/pandas/io/parsers/readers.py", line 620, in _read
    parser = TextFileReader(filepath_or_buffer, **kwds)
  File "/n/home06/vcainamisir/.local/lib/python3.10/site-packages/pandas/io/parsers/readers.py", line 1620, in __init__
    self._engine = self._make_engine(f, self.engine)
  File "/n/home06/vcainamisir/.local/lib/python3.10/site-packages/pandas/io/parsers/readers.py", line 1880, in _make_engine
    self.handles = get_handle(
  File "/n/home06/vcainamisir/.local/lib/python3.10/site-packages/pandas/io/common.py", line 873, in get_handle
    handle = open(
FileNotFoundError: [Errno 2] No such file or directory: 'data/explorescore_sims100_C800_20241209_214747.csv'
Running experiments with C=900
/var/slurmd/spool/slurmd/job61853735/slurm_script: line 35: ./run_experiments.sh: No such file or directory
Error processing results: [Errno 2] No such file or directory: 'data/explorescore_sims100_C900_20241209_214747.csv'
Traceback (most recent call last):
  File "/net/rcstorenfs02/ifs/rc_labs/idreos_lab/users/vcainamisir/2048/2048rl/cpp/plotting/plot_results.py", line 122, in <module>
    main()
  File "/net/rcstorenfs02/ifs/rc_labs/idreos_lab/users/vcainamisir/2048/2048rl/cpp/plotting/plot_results.py", line 115, in main
    output_path = analyze_and_plot(args.csv_file)
  File "/net/rcstorenfs02/ifs/rc_labs/idreos_lab/users/vcainamisir/2048/2048rl/cpp/plotting/plot_results.py", line 79, in analyze_and_plot
    df = pd.read_csv(csv_path)
  File "/n/home06/vcainamisir/.local/lib/python3.10/site-packages/pandas/io/parsers/readers.py", line 1026, in read_csv
    return _read(filepath_or_buffer, kwds)
  File "/n/home06/vcainamisir/.local/lib/python3.10/site-packages/pandas/io/parsers/readers.py", line 620, in _read
    parser = TextFileReader(filepath_or_buffer, **kwds)
  File "/n/home06/vcainamisir/.local/lib/python3.10/site-packages/pandas/io/parsers/readers.py", line 1620, in __init__
    self._engine = self._make_engine(f, self.engine)
  File "/n/home06/vcainamisir/.local/lib/python3.10/site-packages/pandas/io/parsers/readers.py", line 1880, in _make_engine
    self.handles = get_handle(
  File "/n/home06/vcainamisir/.local/lib/python3.10/site-packages/pandas/io/common.py", line 873, in get_handle
    handle = open(
FileNotFoundError: [Errno 2] No such file or directory: 'data/explorescore_sims100_C900_20241209_214747.csv'
Running experiments with C=1000
/var/slurmd/spool/slurmd/job61853735/slurm_script: line 35: ./run_experiments.sh: No such file or directory
Error processing results: [Errno 2] No such file or directory: 'data/explorescore_sims100_C1000_20241209_214747.csv'
Traceback (most recent call last):
  File "/net/rcstorenfs02/ifs/rc_labs/idreos_lab/users/vcainamisir/2048/2048rl/cpp/plotting/plot_results.py", line 122, in <module>
    main()
  File "/net/rcstorenfs02/ifs/rc_labs/idreos_lab/users/vcainamisir/2048/2048rl/cpp/plotting/plot_results.py", line 115, in main
    output_path = analyze_and_plot(args.csv_file)
  File "/net/rcstorenfs02/ifs/rc_labs/idreos_lab/users/vcainamisir/2048/2048rl/cpp/plotting/plot_results.py", line 79, in analyze_and_plot
    df = pd.read_csv(csv_path)
  File "/n/home06/vcainamisir/.local/lib/python3.10/site-packages/pandas/io/parsers/readers.py", line 1026, in read_csv
    return _read(filepath_or_buffer, kwds)
  File "/n/home06/vcainamisir/.local/lib/python3.10/site-packages/pandas/io/parsers/readers.py", line 620, in _read
    parser = TextFileReader(filepath_or_buffer, **kwds)
  File "/n/home06/vcainamisir/.local/lib/python3.10/site-packages/pandas/io/parsers/readers.py", line 1620, in __init__
    self._engine = self._make_engine(f, self.engine)
  File "/n/home06/vcainamisir/.local/lib/python3.10/site-packages/pandas/io/parsers/readers.py", line 1880, in _make_engine
    self.handles = get_handle(
  File "/n/home06/vcainamisir/.local/lib/python3.10/site-packages/pandas/io/common.py", line 873, in get_handle
    handle = open(
FileNotFoundError: [Errno 2] No such file or directory: 'data/explorescore_sims100_C1000_20241209_214747.csv'
Running experiments with C=1100
/var/slurmd/spool/slurmd/job61853735/slurm_script: line 35: ./run_experiments.sh: No such file or directory
Error processing results: [Errno 2] No such file or directory: 'data/explorescore_sims100_C1100_20241209_214747.csv'
Traceback (most recent call last):
  File "/net/rcstorenfs02/ifs/rc_labs/idreos_lab/users/vcainamisir/2048/2048rl/cpp/plotting/plot_results.py", line 122, in <module>
    main()
  File "/net/rcstorenfs02/ifs/rc_labs/idreos_lab/users/vcainamisir/2048/2048rl/cpp/plotting/plot_results.py", line 115, in main
    output_path = analyze_and_plot(args.csv_file)
  File "/net/rcstorenfs02/ifs/rc_labs/idreos_lab/users/vcainamisir/2048/2048rl/cpp/plotting/plot_results.py", line 79, in analyze_and_plot
    df = pd.read_csv(csv_path)
  File "/n/home06/vcainamisir/.local/lib/python3.10/site-packages/pandas/io/parsers/readers.py", line 1026, in read_csv
    return _read(filepath_or_buffer, kwds)
  File "/n/home06/vcainamisir/.local/lib/python3.10/site-packages/pandas/io/parsers/readers.py", line 620, in _read
    parser = TextFileReader(filepath_or_buffer, **kwds)
  File "/n/home06/vcainamisir/.local/lib/python3.10/site-packages/pandas/io/parsers/readers.py", line 1620, in __init__
    self._engine = self._make_engine(f, self.engine)
  File "/n/home06/vcainamisir/.local/lib/python3.10/site-packages/pandas/io/parsers/readers.py", line 1880, in _make_engine
    self.handles = get_handle(
  File "/n/home06/vcainamisir/.local/lib/python3.10/site-packages/pandas/io/common.py", line 873, in get_handle
    handle = open(
FileNotFoundError: [Errno 2] No such file or directory: 'data/explorescore_sims100_C1100_20241209_214747.csv'
Running experiments with C=1200
/var/slurmd/spool/slurmd/job61853735/slurm_script: line 35: ./run_experiments.sh: No such file or directory
Error processing results: [Errno 2] No such file or directory: 'data/explorescore_sims100_C1200_20241209_214747.csv'
Traceback (most recent call last):
  File "/net/rcstorenfs02/ifs/rc_labs/idreos_lab/users/vcainamisir/2048/2048rl/cpp/plotting/plot_results.py", line 122, in <module>
    main()
  File "/net/rcstorenfs02/ifs/rc_labs/idreos_lab/users/vcainamisir/2048/2048rl/cpp/plotting/plot_results.py", line 115, in main
    output_path = analyze_and_plot(args.csv_file)
  File "/net/rcstorenfs02/ifs/rc_labs/idreos_lab/users/vcainamisir/2048/2048rl/cpp/plotting/plot_results.py", line 79, in analyze_and_plot
    df = pd.read_csv(csv_path)
  File "/n/home06/vcainamisir/.local/lib/python3.10/site-packages/pandas/io/parsers/readers.py", line 1026, in read_csv
    return _read(filepath_or_buffer, kwds)
  File "/n/home06/vcainamisir/.local/lib/python3.10/site-packages/pandas/io/parsers/readers.py", line 620, in _read
    parser = TextFileReader(filepath_or_buffer, **kwds)
  File "/n/home06/vcainamisir/.local/lib/python3.10/site-packages/pandas/io/parsers/readers.py", line 1620, in __init__
    self._engine = self._make_engine(f, self.engine)
  File "/n/home06/vcainamisir/.local/lib/python3.10/site-packages/pandas/io/parsers/readers.py", line 1880, in _make_engine
    self.handles = get_handle(
  File "/n/home06/vcainamisir/.local/lib/python3.10/site-packages/pandas/io/common.py", line 873, in get_handle
    handle = open(
FileNotFoundError: [Errno 2] No such file or directory: 'data/explorescore_sims100_C1200_20241209_214747.csv'
Combining results and creating comparison plots...
Traceback (most recent call last):
  File "/net/rcstorenfs02/ifs/rc_labs/idreos_lab/users/vcainamisir/2048/2048rl/cpp/plotting/compare_results.py", line 86, in <module>
    main()
  File "/net/rcstorenfs02/ifs/rc_labs/idreos_lab/users/vcainamisir/2048/2048rl/cpp/plotting/compare_results.py", line 83, in main
    combine_and_compare_results(data_dir, pattern)
  File "/net/rcstorenfs02/ifs/rc_labs/idreos_lab/users/vcainamisir/2048/2048rl/cpp/plotting/compare_results.py", line 34, in combine_and_compare_results
    combined_df = pd.concat(all_data, ignore_index=True)
  File "/n/home06/vcainamisir/.local/lib/python3.10/site-packages/pandas/core/reshape/concat.py", line 382, in concat
    op = _Concatenator(
  File "/n/home06/vcainamisir/.local/lib/python3.10/site-packages/pandas/core/reshape/concat.py", line 445, in __init__
    objs, keys = self._clean_keys_and_objs(objs, keys)
  File "/n/home06/vcainamisir/.local/lib/python3.10/site-packages/pandas/core/reshape/concat.py", line 507, in _clean_keys_and_objs
    raise ValueError("No objects to concatenate")
ValueError: No objects to concatenate
